<robot name="pushing_benchmark">
  <link name="map">
    <inertial>
      <origin xyz="0 0 -0.05"/>
      <mass value="10000"/>
      <inertia ixx="83341.7" ixy="0"       ixz="0"
                             iyy="83341.7" iyz="0"
                                           izz="166667"/>
    </inertial>
    <collision>
      <origin xyz="0. 0. -0.05"/>
      <geometry>
        <box size="10. 10. 0.1"/>
      </geometry>
    </collision>
    <visual>
      <origin xyz="0. 0. -0.05"/>
      <geometry>
        <box size="10. 10. 0.1"/>
      </geometry>
      <material name="gray">
        <color rgba="0.7 0.7 0.7 1.0"/>
      </material>
    </visual>
  </link>

  <link name="pusher">
    <inertial>
      <origin xyz="0 0 0.1"/>
      <mass value="12"/>
      <inertia ixx="0.40" ixy="0"    ixz="0"
                          iyy="0.05" iyz="0"
                                     izz="0.37"/>
    </inertial>
    <collision>
      <origin xyz="0. 0. 0.1"/>
      <geometry>
        <box size="0.1 0.6 0.2"/>
      </geometry>
    </collision>
    <visual>
      <origin xyz="0. 0. 0.1"/>
      <geometry>
        <box size="0.1 0.6 0.2"/>
      </geometry>
      <material name="blue">
        <color rgba="0.7 0.7 1.0 1.0"/>
      </material>
    </visual>
  </link>

  <link name="pushee">
    <inertial>
      <origin xyz="0 0 0.1"/>
      <mass value="6"/>
      <inertia ixx="0.065" ixy="0"     ixz="0"
                           iyy="0.025" iyz="0"
                                       izz="0.050"/>
    </inertial>
    <collision>
      <origin xyz="0. 0. 0.1"/>
      <geometry>
        <box size="0.1 0.3 0.2"/>
      </geometry>
    </collision>
    <visual>
      <origin xyz="0. 0. 0.1"/>
      <geometry>
        <box size="0.1 0.3 0.2"/>
      </geometry>
      <material name="green">
        <color rgba="0.7 1.0 0.7 1.0"/>
      </material>
    </visual>
  </link>

  <joint name="pusher_joint" type="floating">
    <parent link="map"/>
    <child link="pusher"/>
    <origin xyz="-0.2 0 0"/>
  </joint>

  <joint name="pushee" type="floating">
    <parent link="map"/>
    <child link="pushee"/>
    <origin xyz="0.2 0 0" rpy="0 0 0.5"/>
  </joint>
</robot>
